Workbook

Sheet INPUTS
A1: Bancassurance Incentive Engine - Refactored
A3: Total RMs | B3: 500
A4: Current GWP (Cr) | B4: 443
A5: Target GWP (Cr) | B5: 600
A6: Aspirational GWP (Cr) | B6: 800
A7: Current Monthly RM Productivity | B7: 550000
A8: Target Monthly RM Productivity | B8: 750000
A9: Aspirational Monthly RM Productivity | B9: 1000000
A10: RM Base Incentive % | B10: 0.012
A11: ASM Base Incentive % | B11: 0.005
A12: ZSM Base Incentive % | B12: 0.0025
A16: Achievement Weight | B16: 0.5
A17: Activation Weight | B17: 0.2
... A20: Digital Weight | B20: 0.05

Sheet RM_CALCULATOR
A1: RM Name | B1: Zone | C1: Target | D1: Achieved | E1: % Achievement | F1: Activation % | G1: Product Mix % | H1: Persistency % | I1: Digital % | J1: BPI Score | K1: Multiplier | L1: Quality Factor | M1: Final Incentive (Tapered) | N1: Gap to Next Achievement Slab | O1: AI Insight | Q1: Governance & Tapering
A2: RM Alpha | B2: North | C2: 750000 | D2: 550000 | E2: =D2/C2 | F2: 0.5 | G2: 0.3 | H2: 0.8 | I2: 0.8 | J2: =MIN((E2*INPUTS!B16)+(F2*INPUTS!B17)+(G2*INPUTS!B18)+(H2*INPUTS!B19)+(I2*INPUTS!B20),1.5) | K2: =IF(J2<0.6,0.3,IF(J2<0.8,0.6,IF(J2<1,1,IF(J2<1.2,1.5,2)))) | L2: 1 | M2: =IF((D2*INPUTS!B10*K2*L2)<=25000,(D2*INPUTS!B10*K2*L2),IF((D2*INPUTS!B10*K2*L2)<=40000,25000+(((D2*INPUTS!B10*K2*L2)-25000)*0.85),IF((D2*INPUTS!B10*K2*L2)<=75000,37750+(((D2*INPUTS!B10*K2*L2)-40000)*0.70),62250+(((D2*INPUTS!B10*K2*L2)-75000)*0.50)))) | N2: =MAX(IF(E2<0.8,(C2*0.8)-D2,IF(E2<1,(C2*1)-D2,IF(E2<1.2,(C2*1.2)-D2,IF(E2<1.4,(C2*1.4)-D2,(C2*1.5)-D2)))),0) | O2: =IF(E2<0.8,"Increase Sales Volume",IF(F2<0.6,"Activate More Branches",IF(G2<0.5,"Push Focus Products","Strong Performance"))) | Q2: Range | R2: Logic | S2: Action
A3: RM Beta | B3: South | C3: 750000 | D3: 750000 | E3: =D3/C3 | F3: 0.65 | G3: 0.5 | H3: 0.85 | I3: 0.9 | J3: =MIN((E3*INPUTS!B16)+(F3*INPUTS!B17)+(G3*INPUTS!B18)+(H3*INPUTS!B19)+(I3*INPUTS!B20),1.5) | K3: =IF(J3<0.6,0.3,IF(J3<0.8,0.6,IF(J3<1,1,IF(J3<1.2,1.5,2)))) | L3: 1 | M3: =IF((D3*INPUTS!B10*K3*L3)<=25000,(D3*INPUTS!B10*K3*L3),IF((D3*INPUTS!B10*K3*L3)<=40000,25000+(((D3*INPUTS!B10*K3*L3)-25000)*0.85),IF((D3*INPUTS!B10*K3*L3)<=75000,37750+(((D3*INPUTS!B10*K3*L3)-40000)*0.70),62250+(((D3*INPUTS!B10*K3*L3)-75000)*0.50)))) | N3: =MAX(IF(E3<0.8,(C3*0.8)-D3,IF(E3<1,(C3*1)-D3,IF(E3<1.2,(C3*1.2)-D3,IF(E3<1.4,(C3*1.4)-D3,(C3*1.5)-D3)))),0) | O3: =IF(E3<0.8,"Increase Sales Volume",IF(F3<0.6,"Activate More Branches",IF(G3<0.5,"Push Focus Products","Strong Performance"))) | Q3: ₹0–25K | R3: Normal | S3: Automatic
A4: RM Gamma | B4: West | C4: 750000 | D4: 1200000 | E4: =D4/C4 | F4: 0.8 | G4: 0.65 | H4: 0.9 | I4: 0.95 | J4: =MIN((E4*INPUTS!B16)+(F4*INPUTS!B17)+(G4*INPUTS!B18)+(H4*INPUTS!B19)+(I4*INPUTS!B20),1.5) | K4: =IF(J4<0.6,0.3,IF(J4<0.8,0.6,IF(J4<1,1,IF(J4<1.2,1.5,2)))) | L4: 1 | M4: =IF((D4*INPUTS!B10*K4*L4)<=25000,(D4*INPUTS!B10*K4*L4),IF((D4*INPUTS!B10*K4*L4)<=40000,25000+(((D4*INPUTS!B10*K4*L4)-25000)*0.85),IF((D4*INPUTS!B10*K4*L4)<=75000,37750+(((D4*INPUTS!B10*K4*L4)-40000)*0.70),62250+(((D4*INPUTS!B10*K4*L4)-75000)*0.50)))) | N4: =MAX(IF(E4<0.8,(C4*0.8)-D4,IF(E4<1,(C4*1)-D4,IF(E4<1.2,(C4*1.2)-D4,IF(E4<1.4,(C4*1.4)-D4,(C4*1.5)-D4)))),0) | O4: =IF(E4<0.8,"Increase Sales Volume",IF(F4<0.6,"Activate More Branches",IF(G4<0.5,"Push Focus Products","Strong Performance"))) | Q4: ₹25K–40K | R4: Moderated | S4: Monitor
E5: =D5/C5 | J5: =MIN((E5*INPUTS!B16)+(F5*INPUTS!B17)+(G5*INPUTS!B18)+(H5*INPUTS!B19)+(I5*INPUTS!B20),1.5) | K5: =IF(J5<0.6,0.3,IF(J5<0.8,0.6,IF(J5<1,1,IF(J5<1.2,1.5,2)))) | M5: =IF((D5*INPUTS!B10*K5*L5)<=25000,(D5*INPUTS!B10*K5*L5),IF((D5*INPUTS!B10*K5*L5)<=40000,25000+(((D5*INPUTS!B10*K5*L5)-25000)*0.85),IF((D5*INPUTS!B10*K5*L5)<=75000,37750+(((D5*INPUTS!B10*K5*L5)-40000)*0.70),62250+(((D5*INPUTS!B10*K5*L5)-75000)*0.50)))) | N5: =MAX(IF(E5<0.8,(C5*0.8)-D5,IF(E5<1,(C5*1)-D5,IF(E5<1.2,(C5*1.2)-D5,IF(E5<1.4,(C5*1.4)-D5,(C5*1.5)-D5)))),0) | O5: =IF(E5<0.8,"Increase Sales Volume",IF(F5<0.6,"Activate More Branches",IF(G5<0.5,"Push Focus Products","Strong Performance"))) | Q5: ₹40K–75K | R5: Tapered | S5: Review
E6: =D6/C6 | J6: =MIN((E6*INPUTS!B16)+(F6*INPUTS!B17)+(G6*INPUTS!B18)+(H6*INPUTS!B19)+(I6*INPUTS!B20),1.5) | K6: =IF(J6<0.6,0.3,IF(J6<0.8,0.6,IF(J6<1,1,IF(J6<1.2,1.5,2)))) | M6: =IF((D6*INPUTS!B10*K6*L6)<=25000,(D6*INPUTS!B10*K6*L6),IF((D6*INPUTS!B10*K6*L6)<=40000,25000+(((D6*INPUTS!B10*K6*L6)-25000)*0.85),IF((D6*INPUTS!B10*K6*L6)<=75000,37750+(((D6*INPUTS!B10*K6*L6)-40000)*0.70),62250+(((D6*INPUTS!B10*K6*L6)-75000)*0.50)))) | N6: =MAX(IF(E6<0.8,(C6*0.8)-D6,IF(E6<1,(C6*1)-D6,IF(E6<1.2,(C6*1.2)-D6,IF(E6<1.4,(C6*1.4)-D6,(C6*1.5)-D6)))),0) | O6: =IF(E6<0.8,"Increase Sales Volume",IF(F6<0.6,"Activate More Branches",IF(G6<0.5,"Push Focus Products","Strong Performance"))) | Q6: >₹75K | R6: Tapered + Approval | S6: Approval Review
E7: =D7/C7 | J7: =MIN((E7*INPUTS!B16)+(F7*INPUTS!B17)+(G7*INPUTS!B18)+(H7*INPUTS!B19)+(I7*INPUTS!B20),1.5) | K7: =IF(J7<0.6,0.3,IF(J7<0.8,0.6,IF(J7<1,1,IF(J7<1.2,1.5,2)))) | M7: =IF((D7*INPUTS!B10*K7*L7)<=25000,(D7*INPUTS!B10*K7*L7),IF((D7*INPUTS!B10*K7*L7)<=40000,25000+(((D7*INPUTS!B10*K7*L7)-25000)*0.85),IF((D7*INPUTS!B10*K7*L7)<=75000,37750+(((D7*INPUTS!B10*K7*L7)-40000)*0.70),62250+(((D7*INPUTS!B10*K7*L7)-75000)*0.50)))) | N7: =MAX(IF(E7<0.8,(C7*0.8)-D7,IF(E7<1,(C7*1)-D7,IF(E7<1.2,(C7*1.2)-D7,IF(E7<1.4,(C7*1.4)-D7,(C7*1.5)-D7)))),0) | O7: =IF(E7<0.8,"Increase Sales Volume",IF(F7<0.6,"Activate More Branches",IF(G7<0.5,"Push Focus Products","Strong Performance")))
E8: =D8/C8 | J8: =MIN((E8*INPUTS!B16)+(F8*INPUTS!B17)+(G8*INPUTS!B18)+(H8*INPUTS!B19)+(I8*INPUTS!B20),1.5) | K8: =IF(J8<0.6,0.3,IF(J8<0.8,0.6,IF(J8<1,1,IF(J8<1.2,1.5,2)))) | M8: =IF((D8*INPUTS!B10*K8*L8)<=25000,(D8*INPUTS!B10*K8*L8),IF((D8*INPUTS!B10*K8*L8)<=40000,25000+(((D8*INPUTS!B10*K8*L8)-25000)*0.85),IF((D8*INPUTS!B10*K8*L8)<=75000,37750+(((D8*INPUTS!B10*K8*L8)-40000)*0.70),62250+(((D8*INPUTS!B10*K8*L8)-75000)*0.50)))) | N8: =MAX(IF(E8<0.8,(C8*0.8)-D8,IF(E8<1,(C8*1)-D8,IF(E8<1.2,(C8*1.2)-D8,IF(E8<1.4,(C8*1.4)-D8,(C8*1.5)-D8)))),0) | O8: =IF(E8<0.8,"Increase Sales Volume",IF(F8<0.6,"Activate More Branches",IF(G8<0.5,"Push Focus Products","Strong Performance")))
E9: =D9/C9 | J9: =MIN((E9*INPUTS!B16)+(F9*INPUTS!B17)+(G9*INPUTS!B18)+(H9*INPUTS!B19)+(I9*INPUTS!B20),1.5) | K9: =IF(J9<0.6,0.3,IF(J9<0.8,0.6,IF(J9<1,1,IF(J9<1.2,1.5,2)))) | M9: =IF((D9*INPUTS!B10*K9*L9)<=25000,(D9*INPUTS!B10*K9*L9),IF((D9*INPUTS!B10*K9*L9)<=40000,25000+(((D9*INPUTS!B10*K9*L9)-25000)*0.85),IF((D9*INPUTS!B10*K9*L9)<=75000,37750+(((D9*INPUTS!B10*K9*L9)-40000)*0.70),62250+(((D9*INPUTS!B10*K9*L9)-75000)*0.50)))) | N9: =MAX(IF(E9<0.8,(C9*0.8)-D9,IF(E9<1,(C9*1)-D9,IF(E9<1.2,(C9*1.2)-D9,IF(E9<1.4,(C9*1.4)-D9,(C9*1.5)-D9)))),0) | O9: =IF(E9<0.8,"Increase Sales Volume",IF(F9<0.6,"Activate More Branches",IF(G9<0.5,"Push Focus Products","Strong Performance")))
E10: =D10/C10 | J10: =MIN((E10*INPUTS!B16)+(F10*INPUTS!B17)+(G10*INPUTS!B18)+(H10*INPUTS!B19)+(I10*INPUTS!B20),1.5) | K10: =IF(J10<0.6,0.3,IF(J10<0.8,0.6,IF(J10<1,1,IF(J10<1.2,1.5,2)))) | M10: =IF((D10*INPUTS!B10*K10*L10)<=25000,(D10*INPUTS!B10*K10*L10),IF((D10*INPUTS!B10*K10*L10)<=40000,25000+(((D10*INPUTS!B10*K10*L10)-25000)*0.85),IF((D10*INPUTS!B10*K10*L10)<=75000,37750+(((D10*INPUTS!B10*K10*L10)-40000)*0.70),62250+(((D10*INPUTS!B10*K10*L10)-75000)*0.50)))) | N10: =MAX(IF(E10<0.8,(C10*0.8)-D10,IF(E10<1,(C10*1)-D10,IF(E10<1.2,(C10*1.2)-D10,IF(E10<1.4,(C10*1.4)-D10,(C10*1.5)-D10)))),0) | O10: =IF(E10<0.8,"Increase Sales Volume",IF(F10<0.6,"Activate More Branches",IF(G10<0.5,"Push Focus Products","Strong Performance")))
E11: =D11/C11 | J11: =MIN((E11*INPUTS!B16)+(F11*INPUTS!B17)+(G11*INPUTS!B18)+(H11*INPUTS!B19)+(I11*INPUTS!B20),1.5) | K11: =IF(J11<0.6,0.3,IF(J11<0.8,0.6,IF(J11<1,1,IF(J11<1.2,1.5,2)))) | M11: =IF((D11*INPUTS!B10*K11*L11)<=25000,(D11*INPUTS!B10*K11*L11),IF((D11*INPUTS!B10*K11*L11)<=40000,25000+(((D11*INPUTS!B10*K11*L11)-25000)*0.85),IF((D11*INPUTS!B10*K11*L11)<=75000,37750+(((D11*INPUTS!B10*K11*L11)-40000)*0.70),62250+(((D11*INPUTS!B10*K11*L11)-75000)*0.50)))) | N11: =MAX(IF(E11<0.8,(C11*0.8)-D11,IF(E11<1,(C11*1)-D11,IF(E11<1.2,(C11*1.2)-D11,IF(E11<1.4,(C11*1.4)-D11,(C11*1.5)-D11)))),0) | O11: =IF(E11<0.8,"Increase Sales Volume",IF(F11<0.6,"Activate More Branches",IF(G11<0.5,"Push Focus Products","Strong Performance")))
E12: =D12/C12 | J12: =MIN((E12*INPUTS!B16)+(F12*INPUTS!B17)+(G12*INPUTS!B18)+(H12*INPUTS!B19)+(I12*INPUTS!B20),1.5) | K12: =IF(J12<0.6,0.3,IF(J12<0.8,0.6,IF(J12<1,1,IF(J12<1.2,1.5,2)))) | M12: =IF((D12*INPUTS!B10*K12*L12)<=25000,(D12*INPUTS!B10*K12*L12),IF((D12*INPUTS!B10*K12*L12)<=40000,25000+(((D12*INPUTS!B10*K12*L12)-25000)*0.85),IF((D12*INPUTS!B10*K12*L12)<=75000,37750+(((D12*INPUTS!B10*K12*L12)-40000)*0.70),62250+(((D12*INPUTS!B10*K12*L12)-75000)*0.50)))) | N12: =MAX(IF(E12<0.8,(C12*0.8)-D12,IF(E12<1,(C12*1)-D12,IF(E12<1.2,(C12*1.2)-D12,IF(E12<1.4,(C12*1.4)-D12,(C12*1.5)-D12)))),0) | O12: =IF(E12<0.8,"Increase Sales Volume",IF(F12<0.6,"Activate More Branches",IF(G12<0.5,"Push Focus Products","Strong Performance")))
E13: =D13/C13 | J13: =MIN((E13*INPUTS!B16)+(F13*INPUTS!B17)+(G13*INPUTS!B18)+(H13*INPUTS!B19)+(I13*INPUTS!B20),1.5) | K13: =IF(J13<0.6,0.3,IF(J13<0.8,0.6,IF(J13<1,1,IF(J13<1.2,1.5,2)))) | M13: =IF((D13*INPUTS!B10*K13*L13)<=25000,(D13*INPUTS!B10*K13*L13),IF((D13*INPUTS!B10*K13*L13)<=40000,25000+(((D13*INPUTS!B10*K13*L13)-25000)*0.85),IF((D13*INPUTS!B10*K13*L13)<=75000,37750+(((D13*INPUTS!B10*K13*L13)-40000)*0.70),62250+(((D13*INPUTS!B10*K13*L13)-75000)*0.50)))) | N13: =MAX(IF(E13<0.8,(C13*0.8)-D13,IF(E13<1,(C13*1)-D13,IF(E13<1.2,(C13*1.2)-D13,IF(E13<1.4,(C13*1.4)-D13,(C13*1.5)-D13)))),0) | O13: =IF(E13<0.8,"Increase Sales Volume",IF(F13<0.6,"Activate More Branches",IF(G13<0.5,"Push Focus Products","Strong Performance")))
E14: =D14/C14 | J14: =MIN((E14*INPUTS!B16)+(F14*INPUTS!B17)+(G14*INPUTS!B18)+(H14*INPUTS!B19)+(I14*INPUTS!B20),1.5) | K14: =IF(J14<0.6,0.3,IF(J14<0.8,0.6,IF(J14<1,1,IF(J14<1.2,1.5,2)))) | M14: =IF((D14*INPUTS!B10*K14*L14)<=25000,(D14*INPUTS!B10*K14*L14),IF((D14*INPUTS!B10*K14*L14)<=40000,25000+(((D14*INPUTS!B10*K14*L14)-25000)*0.85),IF((D14*INPUTS!B10*K14*L14)<=75000,37750+(((D14*INPUTS!B10*K14*L14)-40000)*0.70),62250+(((D14*INPUTS!B10*K14*L14)-75000)*0.50)))) | N14: =MAX(IF(E14<0.8,(C14*0.8)-D14,IF(E14<1,(C14*1)-D14,IF(E14<1.2,(C14*1.2)-D14,IF(E14<1.4,(C14*1.4)-D14,(C14*1.5)-D14)))),0) | O14: =IF(E14<0.8,"Increase Sales Volume",IF(F14<0.6,"Activate More Branches",IF(G14<0.5,"Push Focus Products","Strong Performance")))
E15: =D15/C15 | J15: =MIN((E15*INPUTS!B16)+(F15*INPUTS!B17)+(G15*INPUTS!B18)+(H15*INPUTS!B19)+(I15*INPUTS!B20),1.5) | K15: =IF(J15<0.6,0.3,IF(J15<0.8,0.6,IF(J15<1,1,IF(J15<1.2,1.5,2)))) | M15: =IF((D15*INPUTS!B10*K15*L15)<=25000,(D15*INPUTS!B10*K15*L15),IF((D15*INPUTS!B10*K15*L15)<=40000,25000+(((D15*INPUTS!B10*K15*L15)-25000)*0.85),IF((D15*INPUTS!B10*K15*L15)<=75000,37750+(((D15*INPUTS!B10*K15*L15)-40000)*0.70),62250+(((D15*INPUTS!B10*K15*L15)-75000)*0.50)))) | N15: =MAX(IF(E15<0.8,(C15*0.8)-D15,IF(E15<1,(C15*1)-D15,IF(E15<1.2,(C15*1.2)-D15,IF(E15<1.4,(C15*1.4)-D15,(C15*1.5)-D15)))),0) | O15: =IF(E15<0.8,"Increase Sales Volume",IF(F15<0.6,"Activate More Branches",IF(G15<0.5,"Push Focus Products","Strong Performance")))
E16: =D16/C16 | J16: =MIN((E16*INPUTS!B16)+(F16*INPUTS!B17)+(G16*INPUTS!B18)+(H16*INPUTS!B19)+(I16*INPUTS!B20),1.5) | K16: =IF(J16<0.6,0.3,IF(J16<0.8,0.6,IF(J16<1,1,IF(J16<1.2,1.5,2)))) | M16: =IF((D16*INPUTS!B10*K16*L16)<=25000,(D16*INPUTS!B10*K16*L16),IF((D16*INPUTS!B10*K16*L16)<=40000,25000+(((D16*INPUTS!B10*K16*L16)-25000)*0.85),IF((D16*INPUTS!B10*K16*L16)<=75000,37750+(((D16*INPUTS!B10*K16*L16)-40000)*0.70),62250+(((D16*INPUTS!B10*K16*L16)-75000)*0.50)))) | N16: =MAX(IF(E16<0.8,(C16*0.8)-D16,IF(E16<1,(C16*1)-D16,IF(E16<1.2,(C16*1.2)-D16,IF(E16<1.4,(C16*1.4)-D16,(C16*1.5)-D16)))),0) | O16: =IF(E16<0.8,"Increase Sales Volume",IF(F16<0.6,"Activate More Branches",IF(G16<0.5,"Push Focus Products","Strong Performance")))
E17: =D17/C17 | J17: =MIN((E17*INPUTS!B16)+(F17*INPUTS!B17)+(G17*INPUTS!B18)+(H17*INPUTS!B19)+(I17*INPUTS!B20),1.5) | K17: =IF(J17<0.6,0.3,IF(J17<0.8,0.6,IF(J17<1,1,IF(J17<1.2,1.5,2)))) | M17: =IF((D17*INPUTS!B10*K17*L17)<=25000,(D17*INPUTS!B10*K17*L17),IF((D17*INPUTS!B10*K17*L17)<=40000,25000+(((D17*INPUTS!B10*K17*L17)-25000)*0.85),IF((D17*INPUTS!B10*K17*L17)<=75000,37750+(((D17*INPUTS!B10*K17*L17)-40000)*0.70),62250+(((D17*INPUTS!B10*K17*L17)-75000)*0.50)))) | N17: =MAX(IF(E17<0.8,(C17*0.8)-D17,IF(E17<1,(C17*1)-D17,IF(E17<1.2,(C17*1.2)-D17,IF(E17<1.4,(C17*1.4)-D17,(C17*1.5)-D17)))),0) | O17: =IF(E17<0.8,"Increase Sales Volume",IF(F17<0.6,"Activate More Branches",IF(G17<0.5,"Push Focus Products","Strong Performance")))
E18: =D18/C18 | J18: =MIN((E18*INPUTS!B16)+(F18*INPUTS!B17)+(G18*INPUTS!B18)+(H18*INPUTS!B19)+(I18*INPUTS!B20),1.5) | K18: =IF(J18<0.6,0.3,IF(J18<0.8,0.6,IF(J18<1,1,IF(J18<1.2,1.5,2)))) | M18: =IF((D18*INPUTS!B10*K18*L18)<=25000,(D18*INPUTS!B10*K18*L18),IF((D18*INPUTS!B10*K18*L18)<=40000,25000+(((D18*INPUTS!B10*K18*L18)-25000)*0.85),IF((D18*INPUTS!B10*K18*L18)<=75000,37750+(((D18*INPUTS!B10*K18*L18)-40000)*0.70),62250+(((D18*INPUTS!B10*K18*L18)-75000)*0.50)))) | N18: =MAX(IF(E18<0.8,(C18*0.8)-D18,IF(E18<1,(C18*1)-D18,IF(E18<1.2,(C18*1.2)-D18,IF(E18<1.4,(C18*1.4)-D18,(C18*1.5)-D18)))),0) | O18: =IF(E18<0.8,"Increase Sales Volume",IF(F18<0.6,"Activate More Branches",IF(G18<0.5,"Push Focus Products","Strong Performance")))
E19: =D19/C19 | J19: =MIN((E19*INPUTS!B16)+(F19*INPUTS!B17)+(G19*INPUTS!B18)+(H19*INPUTS!B19)+(I19*INPUTS!B20),1.5) | K19: =IF(J19<0.6,0.3,IF(J19<0.8,0.6,IF(J19<1,1,IF(J19<1.2,1.5,2)))) | M19: =IF((D19*INPUTS!B10*K19*L19)<=25000,(D19*INPUTS!B10*K19*L19),IF((D19*INPUTS!B10*K19*L19)<=40000,25000+(((D19*INPUTS!B10*K19*L19)-25000)*0.85),IF((D19*INPUTS!B10*K19*L19)<=75000,37750+(((D19*INPUTS!B10*K19*L19)-40000)*0.70),62250+(((D19*INPUTS!B10*K19*L19)-75000)*0.50)))) | N19: =MAX(IF(E19<0.8,(C19*0.8)-D19,IF(E19<1,(C19*1)-D19,IF(E19<1.2,(C19*1.2)-D19,IF(E19<1.4,(C19*1.4)-D19,(C19*1.5)-D19)))),0) | O19: =IF(E19<0.8,"Increase Sales Volume",IF(F19<0.6,"Activate More Branches",IF(G19<0.5,"Push Focus Products","Strong Performance")))
E20: =D20/C20 | J20: =MIN((E20*INPUTS!B16)+(F20*INPUTS!B17)+(G20*INPUTS!B18)+(H20*INPUTS!B19)+(I20*INPUTS!B20),1.5) | K20: =IF(J20<0.6,0.3,IF(J20<0.8,0.6,IF(J20<1,1,IF(J20<1.2,1.5,2)))) | M20: =IF((D20*INPUTS!B10*K20*L20)<=25000,(D20*INPUTS!B10*K20*L20),IF((D20*INPUTS!B10*K20*L20)<=40000,25000+(((D20*INPUTS!B10*K20*L20)-25000)*0.85),IF((D20*INPUTS!B10*K20*L20)<=75000,37750+(((D20*INPUTS!B10*K20*L20)-40000)*0.70),62250+(((D20*INPUTS!B10*K20*L20)-75000)*0.50)))) | N20: =MAX(IF(E20<0.8,(C20*0.8)-D20,IF(E20<1,(C20*1)-D20,IF(E20<1.2,(C20*1.2)-D20,IF(E20<1.4,(C20*1.4)-D20,(C20*1.5)-D20)))),0) | O20: =IF(E20<0.8,"Increase Sales Volume",IF(F20<0.6,"Activate More Branches",IF(G20<0.5,"Push Focus Products","Strong Performance")))
E21: =D21/C21 | J21: =MIN((E21*INPUTS!B16)+(F21*INPUTS!B17)+(G21*INPUTS!B18)+(H21*INPUTS!B19)+(I21*INPUTS!B20),1.5) | K21: =IF(J21<0.6,0.3,IF(J21<0.8,0.6,IF(J21<1,1,IF(J21<1.2,1.5,2)))) | M21: =IF((D21*INPUTS!B10*K21*L21)<=25000,(D21*INPUTS!B10*K21*L21),IF((D21*INPUTS!B10*K21*L21)<=40000,25000+(((D21*INPUTS!B10*K21*L21)-25000)*0.85),IF((D21*INPUTS!B10*K21*L21)<=75000,37750+(((D21*INPUTS!B10*K21*L21)-40000)*0.70),62250+(((D21*INPUTS!B10*K21*L21)-75000)*0.50)))) | N21: =MAX(IF(E21<0.8,(C21*0.8)-D21,IF(E21<1,(C21*1)-D21,IF(E21<1.2,(C21*1.2)-D21,IF(E21<1.4,(C21*1.4)-D21,(C21*1.5)-D21)))),0) | O21: =IF(E21<0.8,"Increase Sales Volume",IF(F21<0.6,"Activate More Branches",IF(G21<0.5,"Push Focus Products","Strong Performance")))
E22: =D22/C22 | J22: =MIN((E22*INPUTS!B16)+(F22*INPUTS!B17)+(G22*INPUTS!B18)+(H22*INPUTS!B19)+(I22*INPUTS!B20),1.5) | K22: =IF(J22<0.6,0.3,IF(J22<0.8,0.6,IF(J22<1,1,IF(J22<1.2,1.5,2)))) | M22: =IF((D22*INPUTS!B10*K22*L22)<=25000,(D22*INPUTS!B10*K22*L22),IF((D22*INPUTS!B10*K22*L22)<=40000,25000+(((D22*INPUTS!B10*K22*L22)-25000)*0.85),IF((D22*INPUTS!B10*K22*L22)<=75000,37750+(((D22*INPUTS!B10*K22*L22)-40000)*0.70),62250+(((D22*INPUTS!B10*K22*L22)-75000)*0.50)))) | N22: =MAX(IF(E22<0.8,(C22*0.8)-D22,IF(E22<1,(C22*1)-D22,IF(E22<1.2,(C22*1.2)-D22,IF(E22<1.4,(C22*1.4)-D22,(C22*1.5)-D22)))),0) | O22: =IF(E22<0.8,"Increase Sales Volume",IF(F22<0.6,"Activate More Branches",IF(G22<0.5,"Push Focus Products","Strong Performance")))
E23: =D23/C23 | J23: =MIN((E23*INPUTS!B16)+(F23*INPUTS!B17)+(G23*INPUTS!B18)+(H23*INPUTS!B19)+(I23*INPUTS!B20),1.5) | K23: =IF(J23<0.6,0.3,IF(J23<0.8,0.6,IF(J23<1,1,IF(J23<1.2,1.5,2)))) | M23: =IF((D23*INPUTS!B10*K23*L23)<=25000,(D23*INPUTS!B10*K23*L23),IF((D23*INPUTS!B10*K23*L23)<=40000,25000+(((D23*INPUTS!B10*K23*L23)-25000)*0.85),IF((D23*INPUTS!B10*K23*L23)<=75000,37750+(((D23*INPUTS!B10*K23*L23)-40000)*0.70),62250+(((D23*INPUTS!B10*K23*L23)-75000)*0.50)))) | N23: =MAX(IF(E23<0.8,(C23*0.8)-D23,IF(E23<1,(C23*1)-D23,IF(E23<1.2,(C23*1.2)-D23,IF(E23<1.4,(C23*1.4)-D23,(C23*1.5)-D23)))),0) | O23: =IF(E23<0.8,"Increase Sales Volume",IF(F23<0.6,"Activate More Branches",IF(G23<0.5,"Push Focus Products","Strong Performance")))
E24: =D24/C24 | J24: =MIN((E24*INPUTS!B16)+(F24*INPUTS!B17)+(G24*INPUTS!B18)+(H24*INPUTS!B19)+(I24*INPUTS!B20),1.5) | K24: =IF(J24<0.6,0.3,IF(J24<0.8,0.6,IF(J24<1,1,IF(J24<1.2,1.5,2)))) | M24: =IF((D24*INPUTS!B10*K24*L24)<=25000,(D24*INPUTS!B10*K24*L24),IF((D24*INPUTS!B10*K24*L24)<=40000,25000+(((D24*INPUTS!B10*K24*L24)-25000)*0.85),IF((D24*INPUTS!B10*K24*L24)<=75000,37750+(((D24*INPUTS!B10*K24*L24)-40000)*0.70),62250+(((D24*INPUTS!B10*K24*L24)-75000)*0.50)))) | N24: =MAX(IF(E24<0.8,(C24*0.8)-D24,IF(E24<1,(C24*1)-D24,IF(E24<1.2,(C24*1.2)-D24,IF(E24<1.4,(C24*1.4)-D24,(C24*1.5)-D24)))),0) | O24: =IF(E24<0.8,"Increase Sales Volume",IF(F24<0.6,"Activate More Branches",IF(G24<0.5,"Push Focus Products","Strong Performance")))
E25: =D25/C25 | J25: =MIN((E25*INPUTS!B16)+(F25*INPUTS!B17)+(G25*INPUTS!B18)+(H25*INPUTS!B19)+(I25*INPUTS!B20),1.5) | K25: =IF(J25<0.6,0.3,IF(J25<0.8,0.6,IF(J25<1,1,IF(J25<1.2,1.5,2)))) | M25: =IF((D25*INPUTS!B10*K25*L25)<=25000,(D25*INPUTS!B10*K25*L25),IF((D25*INPUTS!B10*K25*L25)<=40000,25000+(((D25*INPUTS!B10*K25*L25)-25000)*0.85),IF((D25*INPUTS!B10*K25*L25)<=75000,37750+(((D25*INPUTS!B10*K25*L25)-40000)*0.70),62250+(((D25*INPUTS!B10*K25*L25)-75000)*0.50)))) | N25: =MAX(IF(E25<0.8,(C25*0.8)-D25,IF(E25<1,(C25*1)-D25,IF(E25<1.2,(C25*1.2)-D25,IF(E25<1.4,(C25*1.4)-D25,(C25*1.5)-D25)))),0) | O25: =IF(E25<0.8,"Increase Sales Volume",IF(F25<0.6,"Activate More Branches",IF(G25<0.5,"Push Focus Products","Strong Performance")))
E26: =D26/C26 | J26: =MIN((E26*INPUTS!B16)+(F26*INPUTS!B17)+(G26*INPUTS!B18)+(H26*INPUTS!B19)+(I26*INPUTS!B20),1.5) | K26: =IF(J26<0.6,0.3,IF(J26<0.8,0.6,IF(J26<1,1,IF(J26<1.2,1.5,2)))) | M26: =IF((D26*INPUTS!B10*K26*L26)<=25000,(D26*INPUTS!B10*K26*L26),IF((D26*INPUTS!B10*K26*L26)<=40000,25000+(((D26*INPUTS!B10*K26*L26)-25000)*0.85),IF((D26*INPUTS!B10*K26*L26)<=75000,37750+(((D26*INPUTS!B10*K26*L26)-40000)*0.70),62250+(((D26*INPUTS!B10*K26*L26)-75000)*0.50)))) | N26: =MAX(IF(E26<0.8,(C26*0.8)-D26,IF(E26<1,(C26*1)-D26,IF(E26<1.2,(C26*1.2)-D26,IF(E26<1.4,(C26*1.4)-D26,(C26*1.5)-D26)))),0) | O26: =IF(E26<0.8,"Increase Sales Volume",IF(F26<0.6,"Activate More Branches",IF(G26<0.5,"Push Focus Products","Strong Performance")))
E27: =D27/C27 | J27: =MIN((E27*INPUTS!B16)+(F27*INPUTS!B17)+(G27*INPUTS!B18)+(H27*INPUTS!B19)+(I27*INPUTS!B20),1.5) | K27: =IF(J27<0.6,0.3,IF(J27<0.8,0.6,IF(J27<1,1,IF(J27<1.2,1.5,2)))) | M27: =IF((D27*INPUTS!B10*K27*L27)<=25000,(D27*INPUTS!B10*K27*L27),IF((D27*INPUTS!B10*K27*L27)<=40000,25000+(((D27*INPUTS!B10*K27*L27)-25000)*0.85),IF((D27*INPUTS!B10*K27*L27)<=75000,37750+(((D27*INPUTS!B10*K27*L27)-40000)*0.70),62250+(((D27*INPUTS!B10*K27*L27)-75000)*0.50)))) | N27: =MAX(IF(E27<0.8,(C27*0.8)-D27,IF(E27<1,(C27*1)-D27,IF(E27<1.2,(C27*1.2)-D27,IF(E27<1.4,(C27*1.4)-D27,(C27*1.5)-D27)))),0) | O27: =IF(E27<0.8,"Increase Sales Volume",IF(F27<0.6,"Activate More Branches",IF(G27<0.5,"Push Focus Products","Strong Performance")))
E28: =D28/C28 | J28: =MIN((E28*INPUTS!B16)+(F28*INPUTS!B17)+(G28*INPUTS!B18)+(H28*INPUTS!B19)+(I28*INPUTS!B20),1.5) | K28: =IF(J28<0.6,0.3,IF(J28<0.8,0.6,IF(J28<1,1,IF(J28<1.2,1.5,2)))) | M28: =IF((D28*INPUTS!B10*K28*L28)<=25000,(D28*INPUTS!B10*K28*L28),IF((D28*INPUTS!B10*K28*L28)<=40000,25000+(((D28*INPUTS!B10*K28*L28)-25000)*0.85),IF((D28*INPUTS!B10*K28*L28)<=75000,37750+(((D28*INPUTS!B10*K28*L28)-40000)*0.70),62250+(((D28*INPUTS!B10*K28*L28)-75000)*0.50)))) | N28: =MAX(IF(E28<0.8,(C28*0.8)-D28,IF(E28<1,(C28*1)-D28,IF(E28<1.2,(C28*1.2)-D28,IF(E28<1.4,(C28*1.4)-D28,(C28*1.5)-D28)))),0) | O28: =IF(E28<0.8,"Increase Sales Volume",IF(F28<0.6,"Activate More Branches",IF(G28<0.5,"Push Focus Products","Strong Performance")))
E29: =D29/C29 | J29: =MIN((E29*INPUTS!B16)+(F29*INPUTS!B17)+(G29*INPUTS!B18)+(H29*INPUTS!B19)+(I29*INPUTS!B20),1.5) | K29: =IF(J29<0.6,0.3,IF(J29<0.8,0.6,IF(J29<1,1,IF(J29<1.2,1.5,2)))) | M29: =IF((D29*INPUTS!B10*K29*L29)<=25000,(D29*INPUTS!B10*K29*L29),IF((D29*INPUTS!B10*K29*L29)<=40000,25000+(((D29*INPUTS!B10*K29*L29)-25000)*0.85),IF((D29*INPUTS!B10*K29*L29)<=75000,37750+(((D29*INPUTS!B10*K29*L29)-40000)*0.70),62250+(((D29*INPUTS!B10*K29*L29)-75000)*0.50)))) | N29: =MAX(IF(E29<0.8,(C29*0.8)-D29,IF(E29<1,(C29*1)-D29,IF(E29<1.2,(C29*1.2)-D29,IF(E29<1.4,(C29*1.4)-D29,(C29*1.5)-D29)))),0) | O29: =IF(E29<0.8,"Increase Sales Volume",IF(F29<0.6,"Activate More Branches",IF(G29<0.5,"Push Focus Products","Strong Performance")))
E30: =D30/C30 | J30: =MIN((E30*INPUTS!B16)+(F30*INPUTS!B17)+(G30*INPUTS!B18)+(H30*INPUTS!B19)+(I30*INPUTS!B20),1.5) | K30: =IF(J30<0.6,0.3,IF(J30<0.8,0.6,IF(J30<1,1,IF(J30<1.2,1.5,2)))) | M30: =IF((D30*INPUTS!B10*K30*L30)<=25000,(D30*INPUTS!B10*K30*L30),IF((D30*INPUTS!B10*K30*L30)<=40000,25000+(((D30*INPUTS!B10*K30*L30)-25000)*0.85),IF((D30*INPUTS!B10*K30*L30)<=75000,37750+(((D30*INPUTS!B10*K30*L30)-40000)*0.70),62250+(((D30*INPUTS!B10*K30*L30)-75000)*0.50)))) | N30: =MAX(IF(E30<0.8,(C30*0.8)-D30,IF(E30<1,(C30*1)-D30,IF(E30<1.2,(C30*1.2)-D30,IF(E30<1.4,(C30*1.4)-D30,(C30*1.5)-D30)))),0) | O30: =IF(E30<0.8,"Increase Sales Volume",IF(F30<0.6,"Activate More Branches",IF(G30<0.5,"Push Focus Products","Strong Performance")))
E31: =D31/C31 | J31: =MIN((E31*INPUTS!B16)+(F31*INPUTS!B17)+(G31*INPUTS!B18)+(H31*INPUTS!B19)+(I31*INPUTS!B20),1.5) | K31: =IF(J31<0.6,0.3,IF(J31<0.8,0.6,IF(J31<1,1,IF(J31<1.2,1.5,2)))) | M31: =IF((D31*INPUTS!B10*K31*L31)<=25000,(D31*INPUTS!B10*K31*L31),IF((D31*INPUTS!B10*K31*L31)<=40000,25000+(((D31*INPUTS!B10*K31*L31)-25000)*0.85),IF((D31*INPUTS!B10*K31*L31)<=75000,37750+(((D31*INPUTS!B10*K31*L31)-40000)*0.70),62250+(((D31*INPUTS!B10*K31*L31)-75000)*0.50)))) | N31: =MAX(IF(E31<0.8,(C31*0.8)-D31,IF(E31<1,(C31*1)-D31,IF(E31<1.2,(C31*1.2)-D31,IF(E31<1.4,(C31*1.4)-D31,(C31*1.5)-D31)))),0) | O31: =IF(E31<0.8,"Increase Sales Volume",IF(F31<0.6,"Activate More Branches",IF(G31<0.5,"Push Focus Products","Strong Performance")))
E32: =D32/C32 | J32: =MIN((E32*INPUTS!B16)+(F32*INPUTS!B17)+(G32*INPUTS!B18)+(H32*INPUTS!B19)+(I32*INPUTS!B20),1.5) | K32: =IF(J32<0.6,0.3,IF(J32<0.8,0.6,IF(J32<1,1,IF(J32<1.2,1.5,2)))) | M32: =IF((D32*INPUTS!B10*K32*L32)<=25000,(D32*INPUTS!B10*K32*L32),IF((D32*INPUTS!B10*K32*L32)<=40000,25000+(((D32*INPUTS!B10*K32*L32)-25000)*0.85),IF((D32*INPUTS!B10*K32*L32)<=75000,37750+(((D32*INPUTS!B10*K32*L32)-40000)*0.70),62250+(((D32*INPUTS!B10*K32*L32)-75000)*0.50)))) | N32: =MAX(IF(E32<0.8,(C32*0.8)-D32,IF(E32<1,(C32*1)-D32,IF(E32<1.2,(C32*1.2)-D32,IF(E32<1.4,(C32*1.4)-D32,(C32*1.5)-D32)))),0) | O32: =IF(E32<0.8,"Increase Sales Volume",IF(F32<0.6,"Activate More Branches",IF(G32<0.5,"Push Focus Products","Strong Performance")))
E33: =D33/C33 | J33: =MIN((E33*INPUTS!B16)+(F33*INPUTS!B17)+(G33*INPUTS!B18)+(H33*INPUTS!B19)+(I33*INPUTS!B20),1.5) | K33: =IF(J33<0.6,0.3,IF(J33<0.8,0.6,IF(J33<1,1,IF(J33<1.2,1.5,2)))) | M33: =IF((D33*INPUTS!B10*K33*L33)<=25000,(D33*INPUTS!B10*K33*L33),IF((D33*INPUTS!B10*K33*L33)<=40000,25000+(((D33*INPUTS!B10*K33*L33)-25000)*0.85),IF((D33*INPUTS!B10*K33*L33)<=75000,37750+(((D33*INPUTS!B10*K33*L33)-40000)*0.70),62250+(((D33*INPUTS!B10*K33*L33)-75000)*0.50)))) | N33: =MAX(IF(E33<0.8,(C33*0.8)-D33,IF(E33<1,(C33*1)-D33,IF(E33<1.2,(C33*1.2)-D33,IF(E33<1.4,(C33*1.4)-D33,(C33*1.5)-D33)))),0) | O33: =IF(E33<0.8,"Increase Sales Volume",IF(F33<0.6,"Activate More Branches",IF(G33<0.5,"Push Focus Products","Strong Performance")))
E34: =D34/C34 | J34: =MIN((E34*INPUTS!B16)+(F34*INPUTS!B17)+(G34*INPUTS!B18)+(H34*INPUTS!B19)+(I34*INPUTS!B20),1.5) | K34: =IF(J34<0.6,0.3,IF(J34<0.8,0.6,IF(J34<1,1,IF(J34<1.2,1.5,2)))) | M34: =IF((D34*INPUTS!B10*K34*L34)<=25000,(D34*INPUTS!B10*K34*L34),IF((D34*INPUTS!B10*K34*L34)<=40000,25000+(((D34*INPUTS!B10*K34*L34)-25000)*0.85),IF((D34*INPUTS!B10*K34*L34)<=75000,37750+(((D34*INPUTS!B10*K34*L34)-40000)*0.70),62250+(((D34*INPUTS!B10*K34*L34)-75000)*0.50)))) | N34: =MAX(IF(E34<0.8,(C34*0.8)-D34,IF(E34<1,(C34*1)-D34,IF(E34<1.2,(C34*1.2)-D34,IF(E34<1.4,(C34*1.4)-D34,(C34*1.5)-D34)))),0) | O34: =IF(E34<0.8,"Increase Sales Volume",IF(F34<0.6,"Activate More Branches",IF(G34<0.5,"Push Focus Products","Strong Performance")))
E35: =D35/C35 | J35: =MIN((E35*INPUTS!B16)+(F35*INPUTS!B17)+(G35*INPUTS!B18)+(H35*INPUTS!B19)+(I35*INPUTS!B20),1.5) | K35: =IF(J35<0.6,0.3,IF(J35<0.8,0.6,IF(J35<1,1,IF(J35<1.2,1.5,2)))) | M35: =IF((D35*INPUTS!B10*K35*L35)<=25000,(D35*INPUTS!B10*K35*L35),IF((D35*INPUTS!B10*K35*L35)<=40000,25000+(((D35*INPUTS!B10*K35*L35)-25000)*0.85),IF((D35*INPUTS!B10*K35*L35)<=75000,37750+(((D35*INPUTS!B10*K35*L35)-40000)*0.70),62250+(((D35*INPUTS!B10*K35*L35)-75000)*0.50)))) | N35: =MAX(IF(E35<0.8,(C35*0.8)-D35,IF(E35<1,(C35*1)-D35,IF(E35<1.2,(C35*1.2)-D35,IF(E35<1.4,(C35*1.4)-D35,(C35*1.5)-D35)))),0) | O35: =IF(E35<0.8,"Increase Sales Volume",IF(F35<0.6,"Activate More Branches",IF(G35<0.5,"Push Focus Products","Strong Performance")))
E36: =D36/C36 | J36: =MIN((E36*INPUTS!B16)+(F36*INPUTS!B17)+(G36*INPUTS!B18)+(H36*INPUTS!B19)+(I36*INPUTS!B20),1.5) | K36: =IF(J36<0.6,0.3,IF(J36<0.8,0.6,IF(J36<1,1,IF(J36<1.2,1.5,2)))) | M36: =IF((D36*INPUTS!B10*K36*L36)<=25000,(D36*INPUTS!B10*K36*L36),IF((D36*INPUTS!B10*K36*L36)<=40000,25000+(((D36*INPUTS!B10*K36*L36)-25000)*0.85),IF((D36*INPUTS!B10*K36*L36)<=75000,37750+(((D36*INPUTS!B10*K36*L36)-40000)*0.70),62250+(((D36*INPUTS!B10*K36*L36)-75000)*0.50)))) | N36: =MAX(IF(E36<0.8,(C36*0.8)-D36,IF(E36<1,(C36*1)-D36,IF(E36<1.2,(C36*1.2)-D36,IF(E36<1.4,(C36*1.4)-D36,(C36*1.5)-D36)))),0) | O36: =IF(E36<0.8,"Increase Sales Volume",IF(F36<0.6,"Activate More Branches",IF(G36<0.5,"Push Focus Products","Strong Performance")))
E37: =D37/C37 | J37: =MIN((E37*INPUTS!B16)+(F37*INPUTS!B17)+(G37*INPUTS!B18)+(H37*INPUTS!B19)+(I37*INPUTS!B20),1.5) | K37: =IF(J37<0.6,0.3,IF(J37<0.8,0.6,IF(J37<1,1,IF(J37<1.2,1.5,2)))) | M37: =IF((D37*INPUTS!B10*K37*L37)<=25000,(D37*INPUTS!B10*K37*L37),IF((D37*INPUTS!B10*K37*L37)<=40000,25000+(((D37*INPUTS!B10*K37*L37)-25000)*0.85),IF((D37*INPUTS!B10*K37*L37)<=75000,37750+(((D37*INPUTS!B10*K37*L37)-40000)*0.70),62250+(((D37*INPUTS!B10*K37*L37)-75000)*0.50)))) | N37: =MAX(IF(E37<0.8,(C37*0.8)-D37,IF(E37<1,(C37*1)-D37,IF(E37<1.2,(C37*1.2)-D37,IF(E37<1.4,(C37*1.4)-D37,(C37*1.5)-D37)))),0) | O37: =IF(E37<0.8,"Increase Sales Volume",IF(F37<0.6,"Activate More Branches",IF(G37<0.5,"Push Focus Products","Strong Performance")))
E38: =D38/C38 | J38: =MIN((E38*INPUTS!B16)+(F38*INPUTS!B17)+(G38*INPUTS!B18)+(H38*INPUTS!B19)+(I38*INPUTS!B20),1.5) | K38: =IF(J38<0.6,0.3,IF(J38<0.8,0.6,IF(J38<1,1,IF(J38<1.2,1.5,2)))) | M38: =IF((D38*INPUTS!B10*K38*L38)<=25000,(D38*INPUTS!B10*K38*L38),IF((D38*INPUTS!B10*K38*L38)<=40000,25000+(((D38*INPUTS!B10*K38*L38)-25000)*0.85),IF((D38*INPUTS!B10*K38*L38)<=75000,37750+(((D38*INPUTS!B10*K38*L38)-40000)*0.70),62250+(((D38*INPUTS!B10*K38*L38)-75000)*0.50)))) | N38: =MAX(IF(E38<0.8,(C38*0.8)-D38,IF(E38<1,(C38*1)-D38,IF(E38<1.2,(C38*1.2)-D38,IF(E38<1.4,(C38*1.4)-D38,(C38*1.5)-D38)))),0) | O38: =IF(E38<0.8,"Increase Sales Volume",IF(F38<0.6,"Activate More Branches",IF(G38<0.5,"Push Focus Products","Strong Performance")))
E39: =D39/C39 | J39: =MIN((E39*INPUTS!B16)+(F39*INPUTS!B17)+(G39*INPUTS!B18)+(H39*INPUTS!B19)+(I39*INPUTS!B20),1.5) | K39: =IF(J39<0.6,0.3,IF(J39<0.8,0.6,IF(J39<1,1,IF(J39<1.2,1.5,2)))) | M39: =IF((D39*INPUTS!B10*K39*L39)<=25000,(D39*INPUTS!B10*K39*L39),IF((D39*INPUTS!B10*K39*L39)<=40000,25000+(((D39*INPUTS!B10*K39*L39)-25000)*0.85),IF((D39*INPUTS!B10*K39*L39)<=75000,37750+(((D39*INPUTS!B10*K39*L39)-40000)*0.70),62250+(((D39*INPUTS!B10*K39*L39)-75000)*0.50)))) | N39: =MAX(IF(E39<0.8,(C39*0.8)-D39,IF(E39<1,(C39*1)-D39,IF(E39<1.2,(C39*1.2)-D39,IF(E39<1.4,(C39*1.4)-D39,(C39*1.5)-D39)))),0) | O39: =IF(E39<0.8,"Increase Sales Volume",IF(F39<0.6,"Activate More Branches",IF(G39<0.5,"Push Focus Products","Strong Performance")))
E40: =D40/C40 | J40: =MIN((E40*INPUTS!B16)+(F40*INPUTS!B17)+(G40*INPUTS!B18)+(H40*INPUTS!B19)+(I40*INPUTS!B20),1.5) | K40: =IF(J40<0.6,0.3,IF(J40<0.8,0.6,IF(J40<1,1,IF(J40<1.2,1.5,2)))) | M40: =IF((D40*INPUTS!B10*K40*L40)<=25000,(D40*INPUTS!B10*K40*L40),IF((D40*INPUTS!B10*K40*L40)<=40000,25000+(((D40*INPUTS!B10*K40*L40)-25000)*0.85),IF((D40*INPUTS!B10*K40*L40)<=75000,37750+(((D40*INPUTS!B10*K40*L40)-40000)*0.70),62250+(((D40*INPUTS!B10*K40*L40)-75000)*0.50)))) | N40: =MAX(IF(E40<0.8,(C40*0.8)-D40,IF(E40<1,(C40*1)-D40,IF(E40<1.2,(C40*1.2)-D40,IF(E40<1.4,(C40*1.4)-D40,(C40*1.5)-D40)))),0) | O40: =IF(E40<0.8,"Increase Sales Volume",IF(F40<0.6,"Activate More Branches",IF(G40<0.5,"Push Focus Products","Strong Performance")))
...

Sheet PNL_DASHBOARD
A1: PnL Dashboard
A3: Target Monthly Productivity | B3: =INPUTS!B8
A4: Annual Productivity per RM | B4: =B3*12
A5: Total RM Business | B5: =B4*INPUTS!B3
A6: Base Incentive Cost | B6: =B5*INPUTS!B10
A7: Weighted Multiplier | B7: =(0.3*0.6)+(0.5*1)+(0.2*1.8)
A8: Adjusted Incentive | B8: =B6*B7
A9: ASM Cost | B9: =B5*INPUTS!B11
A10: Estimated Total Cost | B10: =B8+B9
A11: Target GWP | B11: =INPUTS!B5
A12: Incentive % of GWP | B12: =B10/(B11*10000000)

Sheet VERSION_NOTES
A1: Refactor Summary
A3: Removed hard cap
A4: Introduced tapered payout logic
A5: Introduced governance review thresholds
A6: Dynamic achievement slab gap
A7: Behavior-driven acceleration model
A8: Preserved financial governance
